<?xml version="1.0"?>

<robot name="rw" xmlns:xacro="http://www.ros.org/wiki/xacro">

    <xacro:property name="PI" value="3.14159265"/>


    <material name="white">
        <color rgba="1 1 1 1" />
    </material>

    <material name="gray">
        <color rgba="0.7529 0.7529 0.7529 1"/>
    </material>

    <material name="blue">
        <color rgba="0.2 0.2 1 1"/>E
    </material>

    <material name="black">
        <color rgba="0 0 0 1"/>
    </material>

    <material name="red">
        <color rgba="1 0 0 1"/>
    </material>


    <!-- Control Parameters -->
    <xacro:property name="max_linear_acceleration" value="20"/>


    <!-- Body Link -->
    <link name="base_link">
        <visual>
            <origin xyz="0.0 0.0 0.0" rpy="0.0 0.0 0.0"/>
            <geometry>
                <mesh filename="file://$(find rw)/meshes/base_link.stl" />
            </geometry>
            <material name="gray"/>
        </visual>
        <collision>
            <origin xyz="0.0 0.0 0.0" rpy="0.0 0.0 0.0"/>
            <geometry>
                <mesh filename="file://$(find rw)/meshes/base_link.stl" />
            </geometry>
            <material name="gray"/>
        </collision>
        <inertial>
            <mass value="1000"/>
            <inertia ixx="0.5" ixy="0.0" ixz="0.0" iyy="0.5" iyz="0.0" izz="0.5"/>
            <origin xyz="0 0 0" rpy="0 0 0"/>
        </inertial>
    </link>

    <gazebo reference="base_link">
        <mu1>1.0</mu1>
        <mu2>1.0</mu2>
    </gazebo>        

    <!-- BASE_FOOTPRINT LINK -->
    <joint name="base_footprint_joint" type="fixed">
        <origin xyz="0 0 0" rpy="0 0 0"/>
        <parent link="base_link"/>
        <child link="base_footprint"/>
    </joint>

    <link name="base_footprint"> 
    </link>

    <!-- Left Wheel -->
    <link name="wheel_left_link">
        <visual>
            <origin xyz="0.0 0.0 0.0" rpy="0.0 0.0 0.0"/>
            <geometry>
                <mesh filename="file://$(find rw)/meshes/left_wheel.stl" />
            </geometry>
            <material name="black"/>
        </visual>
        <collision>
            <origin xyz="0.0 0.0 0.0" rpy="0.0 0.0 0.0"/>
            <geometry>
                <mesh filename="file://$(find rw)/meshes/left_wheel.stl" />
            </geometry>
            <material name="black"/>
        </collision>
        <inertial>
            <mass value="200"/>
            <inertia ixx="0.1" ixy="0.0" ixz="0.0" iyy="0.1" iyz="0.0" izz="0.2"/>
            <origin xyz="0.0 0.0 0.0" rpy="0.0 0.0 0.0"/>
        </inertial>
    </link>

    <joint name="wheel_left_joint" type="continuous">
        <origin xyz="0 -0.2772 0" rpy="0 0 0" />
        <parent link="base_link"/>
        <child link="wheel_left_link"/>
        <axis xyz="0 1 0"/>
        <limit effort="100" velocity="300.0"/>
        <dynamics damping="1" friction="10"/>
    </joint>

    <gazebo reference="wheel_left_link">
        <mu1>1.0</mu1>
        <mu2>1.0</mu2>
    </gazebo>

    <!-- right Wheel -->
    <link name="wheel_right_link">
        <visual>
            <origin xyz="0.0 0.0 0.0" rpy="0.0 0.0 0.0"/>
            <geometry>
                <mesh filename="file://$(find rw)/meshes/right_wheel.stl" />
            </geometry>
            <material name="black"/>
        </visual>
        <collision>
            <origin xyz="0.0 0.0 0.0" rpy="0.0 0.0 0.0"/>
            <geometry>
                <mesh filename="file://$(find rw)/meshes/right_wheel.stl" />
            </geometry>
            <material name="black"/>
        </collision>
        <inertial>
            <mass value="200"/>
            <inertia ixx="0.1" ixy="0.0" ixz="0.0" iyy="0.1" iyz="0.0" izz="0.2"/>
            <origin xyz="0.0 0.0 0.0" rpy="0.0 0.0 0.0"/>
        </inertial>
    </link>

    <joint name="wheel_right_joint" type="continuous">
        <origin xyz="0.0 0.2772 0" rpy="0 0 0" />
        <parent link="base_link"/>
        <child link="wheel_right_link"/>
        <axis xyz="0 1 0"/>
        <limit effort="100" velocity="300.0"/>
        <dynamics damping="1" friction="10"/>
    </joint>

    <gazebo reference="wheel_right_link">
        <mu1>1.0</mu1>
        <mu2>1.0</mu2>
    </gazebo>

    <!-- FRONT LEFT CASTER WHEEL LINK -->
    <link name="front_left_caster_wheel_link">
        <visual>
            <origin xyz="0.0 0.0 0.0" rpy="0.0 0.0 0.0"/>
            <geometry>
                <mesh filename="file://$(find rw)/meshes/left_casterWheel.stl" />
            </geometry>
            <material name="black"/>
        </visual>
        <collision>
            <origin xyz="0.0 0.0 0.0" rpy="0.0 0.0 0.0"/>
            <geometry>
                <sphere radius="0.11"/>
            </geometry>
            <material name="black"/>
        </collision>
        <inertial>
            <mass value="50"/>
            <inertia ixx="0.0002" ixy="0.0" ixz="0.0" iyy="0.01" iyz="0.0" izz="0.0002"/>
            <origin xyz="0 0 0" rpy="0 0 0"/>
        </inertial>
    </link>

    <joint name="front_left_caster_wheel_joint" type="fixed">
        <origin xyz="-0.6490525 -0.2152957 -0.0024993" rpy="0 0 0"/>
        <parent link="base_link"/>
        <child link="front_left_caster_wheel_link"/>
    </joint>

    <gazebo reference="front_left_caster_wheel_link">
        <mu1>0.01</mu1>
        <mu2>0.01</mu2>
    </gazebo>

    <!-- FRONT RIGHT CASTER WHEEL -->
    <link name="front_right_caster_wheel_link">
        <visual>
            <origin xyz="0.0 0.0 0.0" rpy="0.0 0.0 0.0"/>
            <geometry>
                <mesh filename="file://$(find rw)/meshes/right_casterWheel.stl" />
            </geometry>
            <material name="black"/>
        </visual>
        <collision>
            <origin xyz="0.0 0.0 0.0" rpy="0.0 0.0 0.0"/>
            <geometry>
                 <sphere radius="0.11"/>
            </geometry>
            <material name="black"/>
        </collision>
        <inertial>
            <mass value="50"/>
            <inertia ixx="0.0002" ixy="0.0" ixz="0.0" iyy="0.01" iyz="0.0" izz="0.0002"/>
            <origin xyz="0 0 0" rpy="0 0 0"/>
        </inertial>
    </link>

    <joint name="front_right_caster_wheel_joint" type="fixed">
        <origin xyz="-0.6490525 0.2152957 -0.0024993" rpy="0 0 0"/>
        <parent link="base_link"/>
        <child link="front_right_caster_wheel_link"/>
    </joint>

    <gazebo reference="front_right_caster_wheel_link">
        <mu1>0.01</mu1>
        <mu2>0.01</mu2>
    </gazebo>

    <!-- Back CAMERA -->
    <link name="back_camera_link">
        <visual>
            <geometry>
                <mesh filename="file://$(find rw)/meshes/back_camera.stl" />
            </geometry>
            <material name="blue"/>
        </visual>
        <collision>
            <origin xyz="0.0 0.0 0.0" rpy="0.0 0.0 0.0"/>
            <geometry>
                <mesh filename="file://$(find rw)/meshes/back_camera.stl" />
            </geometry>
            <material name="blue"/>
        </collision>
    </link>

    <joint name="back_camera_joint" type="fixed">
        <parent link="base_link"/>
        <child link="back_camera_link"/>
        <origin xyz="0.0431295 0 0.1042074" rpy="0 0 0"/>
    </joint>

    <link name="back_camera_link_optical"></link>

    <joint name="back_camera_optical_joint" type="fixed">
        <parent link="back_camera_link"/>
        <child link="back_camera_link_optical"/>
        <origin xyz="0.0621685 0 -0.0048553" rpy="0 ${pi/4} 0"/>
    </joint>

    <gazebo reference="back_camera_link_optical">
        <sensor name="rgbd_camera" type="rgbd_camera">
        <camera>
            <horizontal_fov>1.9</horizontal_fov>
            <image>
            <width>640</width>
            <height>640</height>
            </image>
            <clip>
            <near>0.001</near>
            <far>1</far>
            </clip>
            <optical_frame_id>back_camera_link_optical</optical_frame_id>
        </camera>
        <always_on>1</always_on>
        <update_rate>20</update_rate>
        <visualize>true</visualize>
        <topic>camera2</topic>
        <gz_frame_id>back_camera_link</gz_frame_id>
        </sensor>
    </gazebo>

    <!-- Pan and tile kit -->
    <link name="panAndTile_kit">
        <visual>
            <origin xyz="0.0 0.0 0.0" rpy="0.0 0.0 0.0"/>
            <geometry>
                <mesh filename="file://$(find rw)/meshes/panAndTile_kit.stl" />
            </geometry>
            <material name="red"/>
        </visual>
        <collision>
            <origin xyz="0.0 0.0 0.0" rpy="0.0 0.0 0.0"/>
            <geometry>
                <mesh filename="file://$(find rw)/meshes/panAndTile_kit.stl" />
            </geometry>
            <material name="red"/>
        </collision>
        <inertial>
            <mass value="2"/>
            <inertia ixx="0.1" ixy="0.0" ixz="0.0" iyy="0.1" iyz="0.0" izz="0.2"/>
            <origin xyz="0.0 0.0 0.0" rpy="0.0 0.0 0.0"/>
        </inertial>
    </link>

    <joint name="panAndTile_kit_joint" type="continuous">
        <origin xyz="-0.6622757 0.0 0.7159456" rpy="0 0 0" />
        <parent link="base_link"/>
        <child link="panAndTile_kit"/>
        <axis xyz="0 0 1"/>
        <limit effort="100" velocity="300.0"/>
        <dynamics damping="1" friction="1"/>
    </joint>

    <gazebo reference="panAndTile_kit">
        <mu1>1.0</mu1>
        <mu2>1.0</mu2>
    </gazebo>

    <!-- front CAMERA -->
    <link name="front_camera_link">
        <visual>
            <geometry>
                <mesh filename="file://$(find rw)/meshes/front_camera.stl" />
            </geometry>
            <material name="blue"/>
        </visual>
        <collision>
            <origin xyz="0.0 0.0 0.0" rpy="0.0 0.0 0.0"/>
            <geometry>
                <mesh filename="file://$(find rw)/meshes/front_camera.stl" />
            </geometry>
            <material name="blue"/>
        </collision>
    </link>

    <joint name="front_camera_joint" type="fixed">
        <parent link="panAndTile_kit"/>
        <child link="front_camera_link"/>
        <origin xyz="0.0 0.0 0.01" rpy="0 0 0"/>
    </joint>

    <link name="front_camera_link_optical"></link>

    <joint name="front_camera_optical_joint" type="fixed">
        <parent link="front_camera_link"/>
        <child link="front_camera_link_optical"/>
        <origin xyz="-0.0202968 0 0.0228071" rpy="0 -${pi} 0"/>
    </joint>

    <gazebo reference="front_camera_link_optical">
        <sensor name="rgbd_camera" type="rgbd_camera">
        <camera>
            <horizontal_fov>1.25</horizontal_fov>
            <image>
            <width>640</width>
            <height>480</height>
            </image>
            <clip>
            <near>0.3</near>
            <far>15</far>
            </clip>
            <optical_frame_id>front_camera_link_optical</optical_frame_id>
        </camera>
        <always_on>1</always_on>
        <update_rate>20</update_rate>
        <visualize>true</visualize>
        <topic>camera</topic>
        <gz_frame_id>front_camera_link</gz_frame_id>
        </sensor>
    </gazebo>

    <!-- LIDAR -->
    <link name="laser_frame">
        <visual>
            <geometry>
                <mesh filename="file://$(find rw)/meshes/lidar.stl" />
            </geometry>
            <material name="white"/>
        </visual>
        <collision>
            <geometry>
                <mesh filename="file://$(find rw)/meshes/lidar.stl" />
            </geometry>
            <material name="white"/>
        </collision>
    </link>

    <joint name="laser_joint" type="fixed">
        <parent link="panAndTile_kit"/>
        <child link="laser_frame"/>
        <origin xyz="0.0 0.0 0.0556141" rpy="0 0 0"/>
    </joint>

    <link name="lidar_link_optical"></link>

    <joint name="lidar_optical_joint" type="fixed">
        <parent link="laser_frame"/>
        <child link="lidar_link_optical"/>
        <origin xyz="-0.025 0 0.03" rpy="0 -${pi} 0"/>
    </joint>

    <gazebo reference="lidar_link_optical">

        <sensor name="gpu_lidar" type="gpu_lidar">
            <update_rate>30</update_rate>
            <topic>scan</topic>
            <gz_frame_id>lidar_link_optical</gz_frame_id>
            <lidar>
                <scan>
                <horizontal>
                    <samples>50</samples>
                    <!--(max_angle-min_angle)/samples * resolution -->
                    <resolution>1</resolution>
                    <min_angle>${-pi/4}</min_angle>
                    <max_angle>${pi/4}</max_angle>
                </horizontal>
                <!-- Dirty hack for fake lidar detections with ogre 1 rendering in VM -->
                <vertical>
                    <samples>50</samples>
                    <min_angle>${-pi/4}</min_angle>
                    <max_angle>${pi/8}</max_angle>
                </vertical>
                </scan>
                <range>
                <min>0.05</min>
                <max>70</max>
                <resolution>0.01</resolution>
                </range>
                <noise>
                    <type>gaussian</type>
                    <mean>0.0</mean>
                    <stddev>0.01</stddev>
                </noise>
                <frame_id>lidar_link_optical</frame_id>
            </lidar>
            <always_on>1</always_on>
            <visualize>true</visualize>
        </sensor>
    </gazebo>

    <!-- Gazebo Plugins -->
    <gazebo>
        <plugin filename="gz-sim-diff-drive-system" name="gz::sim::systems::DiffDrive">
            <!-- Input -->
            <topic>cmd_vel</topic>
            <!-- <topic>cmd_vel_tracker</topic> -->

            <!-- Wheel joints -->
            <right_joint>wheel_right_joint</right_joint>
            <left_joint>wheel_left_joint</left_joint>
            <!-- Wheel parameters -->
            <wheel_separation>0.554</wheel_separation>
            <wheel_radius>0.113</wheel_radius>
            <!-- Control gains and limits -->
            <max_velocity>400.0</max_velocity>
            <max_linear_acceleration>10</max_linear_acceleration>
            <min_linear_acceleration>-10</min_linear_acceleration>
            <max_angular_acceleration>20</max_angular_acceleration>
            <min_angular_acceleration>-20</min_angular_acceleration>
            <max_linear_velocity>40</max_linear_velocity>
            <min_linear_velocity>-40</min_linear_velocity>
            <max_angular_velocity>10</max_angular_velocity>
            <min_angular_velocity>-10</min_angular_velocity>

            <!-- Output -->
            <odom_topic>odom</odom_topic>                  <!-- Odometry topic -->
            <tf_topic>tf</tf_topic>
            <frame_id>odom</frame_id>
            <child_frame_id>base_link</child_frame_id>
            <odom_publish_frequency>30</odom_publish_frequency>
        </plugin>

        <plugin filename="gz-sim-joint-state-publisher-system" name="gz::sim::systems::JointStatePublisher">
            <topic>joint_states</topic>
            <joint_name>wheel_left_joint</joint_name>
            <joint_name>wheel_right_joint</joint_name>
            <joint_name>panAndTile_kit_joint</joint_name>
        </plugin>

    </gazebo>
</robot>
